Workbook

Sheet Assumptions & Staffing
A1: ASSUMPTIONS & STAFFING MODEL - DETAILED
A3: REVENUE ASSUMPTIONS
A4: Metric | B4: Conservative | C4: Base Case | D4: Optimistic
A5: Spa - Average Treatment Price | B5: 100 | C5: 100 | D5: 100
A6: Spa - Monthly Utilization % | B6: 0.4 | C6: 0.45 | D6: 0.5
A7: Aesthetics - Average Price (Nurse) | B7: 350 | C7: 350 | D7: 350
A8: Aesthetics - Average Price (Other) | B8: 180 | C8: 180 | D8: 180
A9: Spa Month 12 Revenue | B9: 30000 | C9: 40000 | D9: 50000
A10: Aesthetics Month 12 Revenue | B10: 20000 | C10: 30000 | D10: 40000
A11: - Nurse Services (65% of total) | B11: 13000 | C11: 19500 | D11: 26000
A12: - Other Services (35% of total) | B12: 7000 | C12: 10500 | D12: 14000
A15: PAYROLL STRUCTURE (DETAILED)
A16: Role | B16: FTE | C16: Monthly Cost | D16: Annual Cost | E16: Notes
A17: MANAGEMENT & RECEPTION (Shared)
A18: Manager | B18: 1 | C18: 2500 | D18: 30000 | E18: Full-time, manages both spa & clinic
A19: Receptionists | B19: 2 | C19: 2400 | D19: 28800 | E19: 2 FTE shared between spa & clinic
A21: SPA DIVISION
A22: Spa Therapists | B22: 5 | C22: 9000 | D22: 108000 | E22: €1,800 per therapist/month
A24: AESTHETICS/CLINIC DIVISION
A25: Medical Nurse | B25: 1 | C25: 5500 | D25: 66000 | E25: Manages medical aesthetics services
A26: Aesthetics Therapists | B26: 2 | C26: 4000 | D26: 48000 | E26: €2,000 per therapist/month base
A27: Revenue Share (5% of Aes) | C27: Variable | D27: Formula | E27: 5% of total aesthetics revenue
A29: TOTAL BASE PAYROLL | C29: 23400 | D29: 280800 | E29: Excl. revenue share
A32: OPERATING COSTS (NON-PAYROLL)
A33: Cost Category | B33: Monthly | C33: Annual | D33: Type | E33: Notes
A34: FACILITIES
A35: Rent | B35: 5000 | C35: 60000 | D35: Fixed
A36: Utilities | B36: 500 | C36: 6000 | D36: Fixed
A37: Maintenance & Repairs | B37: 300 | C37: 3600 | D37: Fixed
A38: Cleaning & Laundry | B38: 400 | C38: 4800 | D38: Fixed
A40: SYSTEMS & OPERATIONS
A41: Internet & Telephone | B41: 300 | C41: 3600 | D41: Fixed
A42: CRM/Booking System | B42: 80 | C42: 960 | D42: Fixed
A43: Point of Sale | B43: 80 | C43: 960 | D43: Fixed
A45: PROFESSIONAL SERVICES
A46: Accounting & Bookkeeping | B46: 400 | C46: 4800 | D46: Fixed | E46: Combined service
A48: TOTAL FIXED OPERATING COSTS | B48: 7060 | C48: 84720 | D48: Fixed
A51: COST OF GOODS SOLD (COGS) - VARIABLE
A52: Cost Category | B52: Rate | C52: Basis | D52: Notes
A53: Spa Consumables | B53: 3% | C53: of Spa Revenue | D53: Traditional spa supplies
...

Sheet Conservative P&L
A1: CONSERVATIVE CASE - 12 MONTH P&L PROJECTION
A2: Spa only, no clinic operation
A4: Month | B4: Month # | C4: Spa Revenue | D4: Clinic Revenue | E4: Total Revenue | F4: Spa COGS | G4: Clinic COGS | H4: Payroll - Spa | I4: Payroll - Clinic | J4: Rent | K4: Other OpEx | L4: Total OpEx | M4: EBITDA
A5: January | B5: 1 | C5: 30000 | D5: 0 | E5: =C5+D5 | F5: =C5*0.03 | G5: =D5*0.35 | H5: 13900 | I5: 0 | J5: 5000 | K5: 1660 | L5: =F5+G5+H5+I5+J5+K5 | M5: =E5-L5
A6: February | B6: 2 | C6: 30000 | D6: 0 | E6: =C6+D6 | F6: =C6*0.03 | G6: =D6*0.35 | H6: 13900 | I6: 0 | J6: 5000 | K6: 1660 | L6: =F6+G6+H6+I6+J6+K6 | M6: =E6-L6
A7: March | B7: 3 | C7: 30000 | D7: 0 | E7: =C7+D7 | F7: =C7*0.03 | G7: =D7*0.35 | H7: 13900 | I7: 0 | J7: 5000 | K7: 1660 | L7: =F7+G7+H7+I7+J7+K7 | M7: =E7-L7
A8: April | B8: 4 | C8: 30000 | D8: 0 | E8: =C8+D8 | F8: =C8*0.03 | G8: =D8*0.35 | H8: 13900 | I8: 0 | J8: 5000 | K8: 1660 | L8: =F8+G8+H8+I8+J8+K8 | M8: =E8-L8
A9: May | B9: 5 | C9: 30000 | D9: 0 | E9: =C9+D9 | F9: =C9*0.03 | G9: =D9*0.35 | H9: 13900 | I9: 0 | J9: 5000 | K9: 1660 | L9: =F9+G9+H9+I9+J9+K9 | M9: =E9-L9
A10: June | B10: 6 | C10: 30000 | D10: 0 | E10: =C10+D10 | F10: =C10*0.03 | G10: =D10*0.35 | H10: 13900 | I10: 0 | J10: 5000 | K10: 1660 | L10: =F10+G10+H10+I10+J10+K10 | M10: =E10-L10
A11: July | B11: 7 | C11: 30000 | D11: 0 | E11: =C11+D11 | F11: =C11*0.03 | G11: =D11*0.35 | H11: 13900 | I11: 0 | J11: 5000 | K11: 1660 | L11: =F11+G11+H11+I11+J11+K11 | M11: =E11-L11
A12: August | B12: 8 | C12: 30000 | D12: 0 | E12: =C12+D12 | F12: =C12*0.03 | G12: =D12*0.35 | H12: 13900 | I12: 0 | J12: 5000 | K12: 1660 | L12: =F12+G12+H12+I12+J12+K12 | M12: =E12-L12
A13: September | B13: 9 | C13: 30000 | D13: 0 | E13: =C13+D13 | F13: =C13*0.03 | G13: =D13*0.35 | H13: 13900 | I13: 0 | J13: 5000 | K13: 1660 | L13: =F13+G13+H13+I13+J13+K13 | M13: =E13-L13
A14: October | B14: 10 | C14: 30000 | D14: 0 | E14: =C14+D14 | F14: =C14*0.03 | G14: =D14*0.35 | H14: 13900 | I14: 0 | J14: 5000 | K14: 1660 | L14: =F14+G14+H14+I14+J14+K14 | M14: =E14-L14
A15: November | B15: 11 | C15: 30000 | D15: 0 | E15: =C15+D15 | F15: =C15*0.03 | G15: =D15*0.35 | H15: 13900 | I15: 0 | J15: 5000 | K15: 1660 | L15: =F15+G15+H15+I15+J15+K15 | M15: =E15-L15
A16: December | B16: 12 | C16: 30000 | D16: 0 | E16: =C16+D16 | F16: =C16*0.03 | G16: =D16*0.35 | H16: 13900 | I16: 0 | J16: 5000 | K16: 1660 | L16: =F16+G16+H16+I16+J16+K16 | M16: =E16-L16
A17: ANNUAL TOTAL | C17: =SUM(C5:C16) | D17: =SUM(D5:D16) | E17: =SUM(E5:E16) | F17: =SUM(F5:F16) | G17: =SUM(G5:G16) | H17: =SUM(H5:H16) | I17: =SUM(I5:I16) | J17: =SUM(J5:J16) | ... M17: =SUM(M5:M16)

Sheet Base P&L
A1: BASE CASE - 12 MONTH P&L PROJECTION
A2: Spa €30K/month + Clinic ramping €10-20K
A4: Month | B4: Month # | C4: Spa Revenue | D4: Clinic Revenue | E4: Total Revenue | F4: Spa COGS | G4: Clinic COGS | H4: Payroll - Spa | I4: Payroll - Clinic | J4: Rent | K4: Other OpEx | L4: Total OpEx | M4: EBITDA
A5: January | B5: 1 | C5: 30000 | D5: 0 | E5: =C5+D5 | F5: =C5*0.03 | G5: =D5*0.35 | H5: 13900 | I5: 0 | J5: 5000 | K5: 1660 | L5: =F5+G5+H5+I5+J5+K5 | M5: =E5-L5
A6: February | B6: 2 | C6: 30000 | D6: 0 | E6: =C6+D6 | F6: =C6*0.03 | G6: =D6*0.35 | H6: 13900 | I6: 0 | J6: 5000 | K6: 1660 | L6: =F6+G6+H6+I6+J6+K6 | M6: =E6-L6
A7: March | B7: 3 | C7: 30000 | D7: 10000 | E7: =C7+D7 | F7: =C7*0.03 | G7: =D7*0.35 | H7: 13900 | I7: 7220 | J7: 5000 | K7: 1660 | L7: =F7+G7+H7+I7+J7+K7 | M7: =E7-L7
A8: April | B8: 4 | C8: 30000 | D8: 15000 | E8: =C8+D8 | F8: =C8*0.03 | G8: =D8*0.35 | H8: 13900 | I8: 7220 | J8: 5000 | K8: 1660 | L8: =F8+G8+H8+I8+J8+K8 | M8: =E8-L8
A9: May | B9: 5 | C9: 30000 | D9: 20000 | E9: =C9+D9 | F9: =C9*0.03 | G9: =D9*0.35 | H9: 13900 | I9: 7220 | J9: 5000 | K9: 1660 | L9: =F9+G9+H9+I9+J9+K9 | M9: =E9-L9
A10: June | B10: 6 | C10: 30000 | D10: 20000 | E10: =C10+D10 | F10: =C10*0.03 | G10: =D10*0.35 | H10: 13900 | I10: 7220 | J10: 5000 | K10: 1660 | L10: =F10+G10+H10+I10+J10+K10 | M10: =E10-L10
A11: July | B11: 7 | C11: 30000 | D11: 20000 | E11: =C11+D11 | F11: =C11*0.03 | G11: =D11*0.35 | H11: 13900 | I11: 7220 | J11: 5000 | K11: 1660 | L11: =F11+G11+H11+I11+J11+K11 | M11: =E11-L11
A12: August | B12: 8 | C12: 30000 | D12: 20000 | E12: =C12+D12 | F12: =C12*0.03 | G12: =D12*0.35 | H12: 13900 | I12: 7220 | J12: 5000 | K12: 1660 | L12: =F12+G12+H12+I12+J12+K12 | M12: =E12-L12
A13: September | B13: 9 | C13: 30000 | D13: 20000 | E13: =C13+D13 | F13: =C13*0.03 | G13: =D13*0.35 | H13: 13900 | I13: 7220 | J13: 5000 | K13: 1660 | L13: =F13+G13+H13+I13+J13+K13 | M13: =E13-L13
A14: October | B14: 10 | C14: 30000 | D14: 20000 | E14: =C14+D14 | F14: =C14*0.03 | G14: =D14*0.35 | H14: 13900 | I14: 7220 | J14: 5000 | K14: 1660 | L14: =F14+G14+H14+I14+J14+K14 | M14: =E14-L14
A15: November | B15: 11 | C15: 30000 | D15: 20000 | E15: =C15+D15 | F15: =C15*0.03 | G15: =D15*0.35 | H15: 13900 | I15: 7220 | J15: 5000 | K15: 1660 | L15: =F15+G15+H15+I15+J15+K15 | M15: =E15-L15
A16: December | B16: 12 | C16: 30000 | D16: 20000 | E16: =C16+D16 | F16: =C16*0.03 | G16: =D16*0.35 | H16: 13900 | I16: 7220 | J16: 5000 | K16: 1660 | L16: =F16+G16+H16+I16+J16+K16 | M16: =E16-L16
A17: ANNUAL TOTAL | C17: =SUM(C5:C16) | D17: =SUM(D5:D16) | E17: =SUM(E5:E16) | F17: =SUM(F5:F16) | G17: =SUM(G5:G16) | H17: =SUM(H5:H16) | I17: =SUM(I5:I16) | J17: =SUM(J5:J16) | ... M17: =SUM(M5:M16)

Sheet Bull P&L
A1: BULL CASE - 12 MONTH P&L PROJECTION
A2: Spa €45K/month + Clinic ramping aggressively €20-50K
A4: Month | B4: Month # | C4: Spa Revenue | D4: Clinic Revenue | E4: Total Revenue | F4: Spa COGS | G4: Clinic COGS | H4: Payroll - Spa | I4: Payroll - Clinic | J4: Rent | K4: Other OpEx | L4: Total OpEx | M4: EBITDA
A5: January | B5: 1 | C5: 45000 | D5: 0 | E5: =C5+D5 | F5: =C5*0.03 | G5: =D5*0.35 | H5: 13900 | I5: 0 | J5: 5000 | K5: 1660 | L5: =F5+G5+H5+I5+J5+K5 | M5: =E5-L5
A6: February | B6: 2 | C6: 45000 | D6: 0 | E6: =C6+D6 | F6: =C6*0.03 | G6: =D6*0.35 | H6: 13900 | I6: 0 | J6: 5000 | K6: 1660 | L6: =F6+G6+H6+I6+J6+K6 | M6: =E6-L6
A7: March | B7: 3 | C7: 45000 | D7: 20000 | E7: =C7+D7 | F7: =C7*0.03 | G7: =D7*0.35 | H7: 13900 | I7: 7220 | J7: 5000 | K7: 1660 | L7: =F7+G7+H7+I7+J7+K7 | M7: =E7-L7
A8: April | B8: 4 | C8: 45000 | D8: 30000 | E8: =C8+D8 | F8: =C8*0.03 | G8: =D8*0.35 | H8: 13900 | I8: 7220 | J8: 5000 | K8: 1660 | L8: =F8+G8+H8+I8+J8+K8 | M8: =E8-L8
A9: May | B9: 5 | C9: 45000 | D9: 40000 | E9: =C9+D9 | F9: =C9*0.03 | G9: =D9*0.35 | H9: 13900 | I9: 7220 | J9: 5000 | K9: 1660 | L9: =F9+G9+H9+I9+J9+K9 | M9: =E9-L9
A10: June | B10: 6 | C10: 45000 | D10: 45000 | E10: =C10+D10 | F10: =C10*0.03 | G10: =D10*0.35 | H10: 13900 | I10: 7220 | J10: 5000 | K10: 1660 | L10: =F10+G10+H10+I10+J10+K10 | M10: =E10-L10
A11: July | B11: 7 | C11: 45000 | D11: 50000 | E11: =C11+D11 | F11: =C11*0.03 | G11: =D11*0.35 | H11: 13900 | I11: 7220 | J11: 5000 | K11: 1660 | L11: =F11+G11+H11+I11+J11+K11 | M11: =E11-L11
A12: August | B12: 8 | C12: 45000 | D12: 50000 | E12: =C12+D12 | F12: =C12*0.03 | G12: =D12*0.35 | H12: 13900 | I12: 7220 | J12: 5000 | K12: 1660 | L12: =F12+G12+H12+I12+J12+K12 | M12: =E12-L12
A13: September | B13: 9 | C13: 45000 | D13: 50000 | E13: =C13+D13 | F13: =C13*0.03 | G13: =D13*0.35 | H13: 13900 | I13: 7220 | J13: 5000 | K13: 1660 | L13: =F13+G13+H13+I13+J13+K13 | M13: =E13-L13
A14: October | B14: 10 | C14: 45000 | D14: 50000 | E14: =C14+D14 | F14: =C14*0.03 | G14: =D14*0.35 | H14: 13900 | I14: 7220 | J14: 5000 | K14: 1660 | L14: =F14+G14+H14+I14+J14+K14 | M14: =E14-L14
A15: November | B15: 11 | C15: 45000 | D15: 50000 | E15: =C15+D15 | F15: =C15*0.03 | G15: =D15*0.35 | H15: 13900 | I15: 7220 | J15: 5000 | K15: 1660 | L15: =F15+G15+H15+I15+J15+K15 | M15: =E15-L15
A16: December | B16: 12 | C16: 45000 | D16: 50000 | E16: =C16+D16 | F16: =C16*0.03 | G16: =D16*0.35 | H16: 13900 | I16: 7220 | J16: 5000 | K16: 1660 | L16: =F16+G16+H16+I16+J16+K16 | M16: =E16-L16
A17: ANNUAL TOTAL | C17: =SUM(C5:C16) | D17: =SUM(D5:D16) | E17: =SUM(E5:E16) | F17: =SUM(F5:F16) | G17: =SUM(G5:G16) | H17: =SUM(H5:H16) | I17: =SUM(I5:I16) | J17: =SUM(J5:J16) | ... M17: =SUM(M5:M16)

Sheet Scenario Summary
A1: SCENARIO COMPARISON SUMMARY
A3: Metric | B3: Conservative | C3: Base | D3: Bull
A4: Annual Spa Revenue | B4: ='Conservative P&L'!C5*12 | C4: ='Base P&L'!C5*12 | D4: ='Bull P&L'!C5*12
A5: Annual Clinic Revenue | B5: 0 | C5: =SUM('Base P&L'!D5:D16) | D5: =SUM('Bull P&L'!D5:D16)
A6: Total Annual Revenue | B6: =B4+B5 | C6: =C4+C5 | D6: =D4+D5
A7: Annual EBITDA | B7: ='Conservative P&L'!M17 | C7: ='Base P&L'!M17 | D7: ='Bull P&L'!M17
A8: EBITDA Margin | B8: =B7/B6 | C8: =C7/C6 | D8: =D7/D6

Sheet IRR Sensitivity
A1: IRR SENSITIVITY ANALYSIS
A2: Internal Rate of Return across Capex Levels (€)
A4: Capex | B4: Conservative Case | C4: Base Case | D4: Bull Case
A5: 300000 | B5: =IRR({-300000,'Conservative P&L'!M17,'Conservative P&L'!M17,'Conservative P&L'!M17,'Conservative P&L'!M17,'Conservative P&L'!M17}) | C5: =IRR({-300000,'Base P&L'!M17,'Base P&L'!M17,'Base P&L'!M17,'Base P&L'!M17,'Base P&L'!M17}) | D5: =IRR({-300000,'Bull P&L'!M17,'Bull P&L'!M17,'Bull P&L'!M17,'Bull P&L'!M17,'Bull P&L'!M17})
A6: 400000 | B6: =IRR({-400000,'Conservative P&L'!M17,'Conservative P&L'!M17,'Conservative P&L'!M17,'Conservative P&L'!M17,'Conservative P&L'!M17}) | C6: =IRR({-400000,'Base P&L'!M17,'Base P&L'!M17,'Base P&L'!M17,'Base P&L'!M17,'Base P&L'!M17}) | D6: =IRR({-400000,'Bull P&L'!M17,'Bull P&L'!M17,'Bull P&L'!M17,'Bull P&L'!M17,'Bull P&L'!M17})
A7: 500000 | B7: =IRR({-500000,'Conservative P&L'!M17,'Conservative P&L'!M17,'Conservative P&L'!M17,'Conservative P&L'!M17,'Conservative P&L'!M17}) | C7: =IRR({-500000,'Base P&L'!M17,'Base P&L'!M17,'Base P&L'!M17,'Base P&L'!M17,'Base P&L'!M17}) | D7: =IRR({-500000,'Bull P&L'!M17,'Bull P&L'!M17,'Bull P&L'!M17,'Bull P&L'!M17,'Bull P&L'!M17})
A8: 600000 | B8: =IRR({-600000,'Conservative P&L'!M17,'Conservative P&L'!M17,'Conservative P&L'!M17,'Conservative P&L'!M17,'Conservative P&L'!M17}) | C8: =IRR({-600000,'Base P&L'!M17,'Base P&L'!M17,'Base P&L'!M17,'Base P&L'!M17,'Base P&L'!M17}) | D8: =IRR({-600000,'Bull P&L'!M17,'Bull P&L'!M17,'Bull P&L'!M17,'Bull P&L'!M17,'Bull P&L'!M17})
A9: 700000 | B9: =IRR({-700000,'Conservative P&L'!M17,'Conservative P&L'!M17,'Conservative P&L'!M17,'Conservative P&L'!M17,'Conservative P&L'!M17}) | C9: =IRR({-700000,'Base P&L'!M17,'Base P&L'!M17,'Base P&L'!M17,'Base P&L'!M17,'Base P&L'!M17}) | D9: =IRR({-700000,'Bull P&L'!M17,'Bull P&L'!M17,'Bull P&L'!M17,'Bull P&L'!M17,'Bull P&L'!M17})

Sheet Payback Period Sensitivity
A1: PAYBACK PERIOD SENSITIVITY ANALYSIS
A2: Payback Period in Years across Capex Levels (€)
A4: Capex | B4: Conservative Case | C4: Base Case | D4: Bull Case
A5: 300000 | B5: =$300000/'Conservative P&L'!M17 | C5: =$300000/'Base P&L'!M17 | D5: =$300000/'Bull P&L'!M17
A6: 400000 | B6: =$400000/'Conservative P&L'!M17 | C6: =$400000/'Base P&L'!M17 | D6: =$400000/'Bull P&L'!M17
A7: 500000 | B7: =$500000/'Conservative P&L'!M17 | C7: =$500000/'Base P&L'!M17 | D7: =$500000/'Bull P&L'!M17
A8: 600000 | B8: =$600000/'Conservative P&L'!M17 | C8: =$600000/'Base P&L'!M17 | D8: =$600000/'Bull P&L'!M17
A9: 700000 | B9: =$700000/'Conservative P&L'!M17 | C9: =$700000/'Base P&L'!M17 | D9: =$700000/'Bull P&L'!M17
A12: Note: Payback Period = Years to recover capex at current EBITDA

Sheet Negotiation & Key Notes
A1: NEGOTIATION STRATEGY & KEY CONSIDERATIONS
A3: CRITICAL PRINCIPLE:
A4: Price the CURRENT business value, not your future potential. The clinic is YOUR advantage, not the seller's.
A6: YOUR BATNA & LEVERAGE POSITION
A7: ✓ You have zero urgency | B7: Seller reached out, not vice versa
A8: ✓ Business is currently loss-making | B8: At €8K+ rent, monthly EBITDA is negative (CURRENT STATE)
A9: ✓ Owner is disengaged | B9: Has not invested in operations for 2+ years
A10: ✓ Equipment is worth far less than capex | B10: Fair market value €150-200K vs €1M capex invested
A11: ✓ Lease is conditional on landlord approval | B11: Unknown if assignment is freely given or costs extra
A14: KEY ARGUMENTS FOR LOWER PRICING
A15: KILLER ARGUMENTS (Use First)
A16: → Sunk Cost Fallacy | B16: Your €1M investment is already gone. Selling doesn't create the loss—it STOPS additional losses.
A17: → Business Model is Negative at Current Rent | B17: At €8K rent, monthly EBITDA = -€850. This is a LOSS-MAKING business. No buyer prices a losing business above asset value.
A18: → Revenue Collapsed 50% | B18: Peak was €40-50K/month; now €20-25K. Why? What changed? Until you diagnose this, the business is high-risk.
A19: → Equipment Appraisal is Required | B19: Let's get independent valuation. FMV is likely €150-200K. This removes emotional guessing.
A22: PRICE ANCHOR STRATEGY (Ackermann Sequence)
A23: Stage | B23: Price | C23: Conditional Upon
A24: 1. Anchor (Opening) | B24: 40000 | C24: No conditions - establish opening range
A25: 2. Move 1 | B25: 70000 | C25: + Equipment appraisal + Landlord assignment confirmation
A26: 3. Move 2 | B26: 100000 | C26: + 24-month P&L documentation + Revenue decline diagnosis
A27: 4. Move 3 | B27: 125000 | C27: "We're very close" conversation
A28: 5. Final | B28: 150000 | C28: + 45-day close + Indemnification + Mutual legal fees
A31: POWER SCRIPTS (Exact Phrasing)
A32: On Sunk Cost | B32: "I understand completely why you look at what was put into this place and feel the number should reflect that. But the market—any buyer—asks one question: what does this business earn TODAY? Not what it cost to build. That's just how acquisitions are priced."
A33: On Revenue Decline | B33: "The revenue is down 50% from peak. My job is to understand why. That's not criticism; it's risk assessment. Until we diagnose it, every buyer assumes it's structural. Let's pull 24 months of P&L together and talk about it."
A34: On Equipment | B34: "Let's get a neutral third-party equipment appraisal. It protects both of us. If it comes back higher than my estimate, we adjust. Fair?"
A35: Closing Technique | B35: "It sounds like if we land somewhere around [TARGET], we'd have a deal. Am I reading that right?"
A38: RED LINES (Walk Away If...)
A39: 1. Rent > €10K/month AND seller demands > €250K
A40: 2. Undisclosed equipment financing or business debts
A41: 3. Landlord consent uncertain or will cost material premium (>€5K)
A42: 4. Revenue significantly below stated (>20% variance)
A43: 5. Unresolved Numi legal complications
A44: 6. After 3 Ackermann moves, seller still anchored > €200K without movement
A47: MEETING PROTOCOL (4 ACTS)
A48: ACT 1: Intelligence (20-30 min) | B48: Ask 5 questions: biggest challenge? Monthly picture? Success looks like? Timeframe? Other conversations? REVEAL NOTHING.
A49: ACT 2: Reframe (20-30 min) | B49: Introduce equipment appraisal. Present EBITDA framework. Redirect from sunk cost to forward earnings.
A50: ACT 3: The Offer (20-30 min) | B50: Drop anchor €40K. Hold silence. Use Ackermann sequence. React with questions, not counter-offers.
A51: ACT 4: Close or Exit (10-15 min) | B51: Trial close OR graceful exit. NEVER close today. "Every month has a cost. I'll be in touch in a few days."
A54: CRITICAL DUE DILIGENCE ITEMS (Before Price Agreement)
...

Sheet Negotiation Briefing
A1: # INA Spa Malta — Negotiation Briefing
A2: ## Prepared for Meeting with Seller
A4: **Date:** February 22, 2026
A5: **Venue:** [TBD]
A6: **Duration:** 90 minutes (4 acts)
A7: **Objective:** Acquire lease + equipment + operations at optimal price through disciplined negotiation
A9: ---
A11: ## Your Position at a Glance
A13: | Metric | Your Reality | Seller's Perception |
A14: |---|---|---|
A15: | **Current Revenue** | €30K/month spa (conservative baseline) | €20-25K/month (down from peak) |
A16: | **Current EBITDA** | €123.4K/year (Base Case with clinic ramp) | ~€86K/year (at mid-rent) |
... A317: Go in there and negotiate like it.

Sheet Quick Reference
A1: ═══════════════════════════════════════════════════════════════════════════════
A2: INA SPA MALTA — MEETING QUICK REFERENCE
A3: February 22, 2026
A4: ═══════════════════════════════════════════════════════════════════════════════
A6: MINDSET BEFORE YOU WALK IN
A7: ━━━━━━━━━━━━━━━━━━━━━━━━━━━━━━━━━━━━━━━━━━━━━━━━━━━━━━━━━━━━━━━━━━━━━━━━━━━━
A8: ✓ I'm evaluating. Haven't decided yet.
A9: ✓ This must work for MY business.
A10: ✓ I'm fair. If numbers don't work, I walk calmly.
A12: ═══════════════════════════════════════════════════════════════════════════════
A14: THE THREE NUMBERS
A15: ━━━━━━━━━━━━━━━━━━━━━━━━━━━━━━━━━━━━━━━━━━━━━━━━━━━━━━━━━━━━━━━━━━━━━━━━━━━━
... A223: ═══════════════════════════════════════════════════════════════════════════════

Sheet Execution Index
A1: # INA Spa Malta — Acquisition Execution Index
A2: ## Complete Roadmap: Plan → Analysis → Negotiation → Close
A4: **Prepared:** February 22, 2026
A5: **Status:** Ready for Seller Meeting
A6: **Last Updated:** Feb 22, 2026
A8: ---
A10: ## Your Complete Toolkit
A12: You now have 4 integrated documents that work together to execute this acquisition:
A14: ### 1. **INA-Spa-Consolidated-Model.xlsx** (The Financial Foundation)
A15: **Purpose:** Quantified business analysis with scenarios
A16: **Use When:** Due diligence, post-meeting analysis, decision validation
A17: **Contains:**
... A333: **Ready for Deployment:** ✓

Sheet Annual Summary & KPIs
A1: ANNUAL SUMMARY & KPIs (YEAR 1 - BASE CASE)
A3: REVENUE ANALYSIS
A4: Spa Revenue (Year 1) | B4: =SUM('Monthly P&L - Detailed'!B4:M4)
A5: Nurse Services Revenue | B5: =SUM('Monthly P&L - Detailed'!B5:M5)
A6: Other Aesthetics Revenue | B6: =SUM('Monthly P&L - Detailed'!B6:M6)
A7: Total Aesthetics Revenue | B7: =SUM('Monthly P&L - Detailed'!B7:M7)
A8: TOTAL REVENUE (Year 1) | B8: =SUM('Monthly P&L - Detailed'!B8:M8)
A10: PAYROLL ANALYSIS
A11: Manager (Shared) | B11: =SUM('Monthly P&L - Detailed'!B11:M11)
A12: Receptionists (Shared) | B12: =SUM('Monthly P&L - Detailed'!B12:M12)
A13: Spa Therapists | B13: =SUM('Monthly P&L - Detailed'!B13:M13)
A14: Medical Nurse (Clinic only) | B14: =SUM('Monthly P&L - Detailed'!B14:M14)
A15: Aesthetics Therapists (Clinic only) | B15: =SUM('Monthly P&L - Detailed'!B15:M15)
A16: Revenue Share (5% Aesthetics) | B16: =SUM('Monthly P&L - Detailed'!B16:M16)
A17: TOTAL PAYROLL (Year 1) | B17: =SUM('Monthly P&L - Detailed'!B17:M17)
A19: OPERATING COSTS ANALYSIS
A20: Total Fixed OpEx | B20: =SUM('Monthly P&L - Detailed'!B28:M28)
A21: Total COGS & Variable | B21: =SUM('Monthly P&L - Detailed'!B36:M36)
A22: TOTAL COSTS (Year 1) | B22: =B20+B21
A24: PROFITABILITY
A25: YEAR 1 EBITDA | B25: =SUM('Monthly P&L - Detailed'!B44:M44)
A26: EBITDA Margin | B26: =B25/B8
A28: KEY EFFICIENCY METRICS
A29: Payroll % of Revenue | B29: =B17/B8
A30: OpEx % of Revenue (excl. COGS) | B30: =B20/B8
A31: COGS/Variable % of Revenue | B31: =B21/B8
A33: VALUATION FRAMEWORK
A34: Year 1 EBITDA | B34: =B25
A35: EBITDA Multiple (5x - Conservative) | B35: =B34*5
A36: EBITDA Multiple (6x - Fair Value) | B36: =B34*6
A37: Enterprise Value (Fair) | B37: =B36
A39: ACQUISITION PRICE FRAMEWORK
A40: Opening Offer (Anchor) | B40: 40000
A41: Target Offer (65% of Fair) | B41: =B37*0.65
A42: Walk-Away Price (BATNA Ceiling) | B42: 150000

Sheet Monthly P&L
A1: 12-MONTH P&L PROJECTION (BASE CASE - DETAILED COST BREAKDOWN)
A2: Month | B2: M1 | C2: M2 | D2: M3 | E2: M4 | F2: M5 | G2: M6 | H2: M7 | I2: M8 | J2: M9 | K2: M10 | L2: M11 | M2: M12
A3: REVENUE
A4: Spa Revenue | B4: 24000 | C4: 28000 | D4: 32000 | E4: 33000 | F4: 31000 | G4: 34000 | H4: 37000 | I4: 43000 | J4: 42000 | K4: 40000 | L4: 36000 | M4: 38000
A5: Nurse Services Revenue | B5: 0 | C5: 0 | D5: 6500 | E5: 9750 | F5: 11700 | G5: 13000 | H5: 13650 | I5: 14950 | J5: 15600 | K5: 16250 | L5: 17550 | M5: 19500
A6: Other Aesthetics Revenue | B6: 0 | C6: 0 | D6: 3500 | E6: 5250 | F6: 6300 | G6: 7000 | H6: 7350 | I6: 8050 | J6: 8400 | K6: 8750 | L6: 9450 | M6: 10500
A7: Aesthetics Revenue (Total) | B7: =B5+B6 | C7: =C5+C6 | D7: =D5+D6 | E7: =E5+E6 | F7: =F5+F6 | G7: =G5+G6 | H7: =H5+H6 | I7: =I5+I6 | ... M7: =M5+M6
A8: TOTAL REVENUE | B8: =B4+B7 | C8: =C4+C7 | D8: =D4+D7 | E8: =E4+E7 | F8: =F4+F7 | G8: =G4+G7 | H8: =H4+H7 | I8: =I4+I7 | ... M8: =M4+M7
A10: PAYROLL COSTS
A11: Manager (Shared) | B11: 2500 | C11: 2500 | D11: 2500 | E11: 2500 | F11: 2500 | G11: 2500 | H11: 2500 | I11: 2500 | J11: 2500 | K11: 2500 | L11: 2500 | M11: 2500
A12: Receptionists (Shared) | B12: 2400 | C12: 2400 | D12: 2400 | E12: 2400 | F12: 2400 | G12: 2400 | H12: 2400 | I12: 2400 | J12: 2400 | K12: 2400 | L12: 2400 | M12: 2400
A13: Spa Therapists | B13: 9000 | C13: 9000 | D13: 9000 | E13: 9000 | F13: 9000 | G13: 9000 | H13: 9000 | I13: 9000 | J13: 9000 | K13: 9000 | L13: 9000 | M13: 9000
A14: Medical Nurse | B14: 0 | C14: 0 | D14: 5500 | E14: 5500 | F14: 5500 | G14: 5500 | H14: 5500 | I14: 5500 | J14: 5500 | K14: 5500 | L14: 5500 | M14: 5500
A15: Aesthetics Therapists | B15: 0 | C15: 0 | D15: 4000 | E15: 4000 | F15: 4000 | G15: 4000 | H15: 4000 | I15: 4000 | J15: 4000 | K15: 4000 | L15: 4000 | M15: 4000
A16: Revenue Share (5% Aesthetics) | B16: 0 | C16: 0 | D16: =D7*0.05 | E16: =E7*0.05 | F16: =F7*0.05 | G16: =G7*0.05 | H16: =H7*0.05 | I16: =I7*0.05 | J16: =J7*0.05 | K16: =K7*0.05 | ... M16: =M7*0.05
A17: TOTAL PAYROLL | B17: =B11+B12+B13+B14+B15+B16 | C17: =C11+C12+C13+C14+C15+C16 | D17: =D11+D12+D13+D14+D15+D16 | E17: =E11+E12+E13+E14+E15+E16 | F17: =F11+F12+F13+F14+F15+F16 | G17: =G11+G12+G13+G14+G15+G16 | H17: =H11+H12+H13+H14+H15+H16 | I17: =I11+I12+I13+I14+I15+I16 | ... M17: =M11+M12+M13+M14+M15+M16
A19: OPERATING COSTS (Non-Payroll)
A20: Rent | B20: 5000 | C20: 5000 | D20: 5000 | E20: 5000 | F20: 5000 | G20: 5000 | H20: 5000 | I20: 5000 | J20: 5000 | K20: 5000 | L20: 5000 | M20: 5000
A21: Utilities | B21: 500 | C21: 500 | D21: 500 | E21: 500 | F21: 500 | G21: 500 | H21: 500 | I21: 500 | J21: 500 | K21: 500 | L21: 500 | M21: 500
A22: Maintenance & Repairs | B22: 300 | C22: 300 | D22: 300 | E22: 300 | F22: 300 | G22: 300 | H22: 300 | I22: 300 | J22: 300 | K22: 300 | L22: 300 | M22: 300
A23: Cleaning & Laundry | B23: 400 | C23: 400 | D23: 400 | E23: 400 | F23: 400 | G23: 400 | H23: 400 | I23: 400 | J23: 400 | K23: 400 | L23: 400 | M23: 400
A24: Internet & Telephone | B24: 300 | C24: 300 | D24: 300 | E24: 300 | F24: 300 | G24: 300 | H24: 300 | I24: 300 | J24: 300 | K24: 300 | L24: 300 | M24: 300
A25: CRM/Booking System | B25: 80 | C25: 80 | D25: 80 | E25: 80 | F25: 80 | G25: 80 | H25: 80 | I25: 80 | J25: 80 | K25: 80 | L25: 80 | M25: 80
A26: Point of Sale | B26: 80 | C26: 80 | D26: 80 | E26: 80 | F26: 80 | G26: 80 | H26: 80 | I26: 80 | J26: 80 | K26: 80 | L26: 80 | M26: 80
A27: Accounting & Bookkeeping | B27: 400 | C27: 400 | D27: 400 | E27: 400 | F27: 400 | G27: 400 | H27: 400 | I27: 400 | J27: 400 | K27: 400 | L27: 400 | M27: 400
A28: TOTAL FIXED OPEX | B28: =B20+B21+B22+B23+B24+B25+B26+B27 | C28: =C20+C21+C22+C23+C24+C25+C26+C27 | D28: =D20+D21+D22+D23+D24+D25+D26+D27 | E28: =E20+E21+E22+E23+E24+E25+E26+E27 | F28: =F20+F21+F22+F23+F24+F25+F26+F27 | G28: =G20+G21+G22+G23+G24+G25+G26+G27 | H28: =H20+H21+H22+H23+H24+H25+H26+H27 | I28: =I20+I21+I22+I23+I24+I25+I26+I27 | ... M28: =M20+M21+M22+M23+M24+M25+M26+M27
A30: COST OF GOODS SOLD (COGS)
A31: Spa Consumables (3% of Spa) | B31: =B4*0.03 | C31: =C4*0.03 | D31: =D4*0.03 | E31: =E4*0.03 | F31: =F4*0.03 | G31: =G4*0.03 | H31: =H4*0.03 | I31: =I4*0.03 | ... M31: =M4*0.03
A32: Nurse Services COGS (35% of Nurse) | B32: =B5*0.35 | C32: =C5*0.35 | D32: =D5*0.35 | E32: =E5*0.35 | F32: =F5*0.35 | G32: =G5*0.35 | H32: =H5*0.35 | I32: =I5*0.35 | ... M32: =M5*0.35
A33: Other Aesthetics COGS (5% of Other) | B33: =B6*0.05 | C33: =C6*0.05 | D33: =D6*0.05 | E33: =E6*0.05 | F33: =F6*0.05 | G33: =G6*0.05 | H33: =H6*0.05 | I33: =I6*0.05 | ... M33: =M6*0.05
A34: Hotel Partnership (5% of Spa) | B34: =B4*0.05 | C34: =C4*0.05 | D34: =D4*0.05 | E34: =E4*0.05 | F34: =F4*0.05 | G34: =G4*0.05 | H34: =H4*0.05 | I34: =I4*0.05 | ... M34: =M4*0.05
A35: Contingency (2% of Total) | B35: =B8*0.02 | C35: =C8*0.02 | D35: =D8*0.02 | E35: =E8*0.02 | F35: =F8*0.02 | G35: =G8*0.02 | H35: =H8*0.02 | I35: =I8*0.02 | ... M35: =M8*0.02
A36: TOTAL COGS & VARIABLE | B36: =B31+B32+B33+B34+B35 | C36: =C31+C32+C33+C34+C35 | D36: =D31+D32+D33+D34+D35 | E36: =E31+E32+E33+E34+E35 | F36: =F31+F32+F33+F34+F35 | G36: =G31+G32+G33+G34+G35 | H36: =H31+H32+H33+H34+H35 | I36: =I31+I32+I33+I34+I35 | ... M36: =M31+M32+M33+M34+M35
A38: COST SUMMARY
A39: Total Payroll | B39: =B17 | C39: =C17 | D39: =D17 | E39: =E17 | F39: =F17 | G39: =G17 | H39: =H17 | I39: =I17 | ... M39: =M17
A40: Total Fixed OpEx | B40: =B28 | C40: =C28 | D40: =D28 | E40: =E28 | F40: =F28 | G40: =G28 | H40: =H28 | I40: =I28 | ... M40: =M28
A41: Total COGS & Variable | B41: =B36 | C41: =C36 | D41: =D36 | E41: =E36 | F41: =F36 | G41: =G36 | H41: =H36 | I41: =I36 | ... M41: =M36
A42: TOTAL COSTS | B42: =B39+B40+B41 | C42: =C39+C40+C41 | D42: =D39+D40+D41 | E42: =E39+E40+E41 | F42: =F39+F40+F41 | G42: =G39+G40+G41 | H42: =H39+H40+H41 | I42: =I39+I40+I41 | ... M42: =M39+M40+M41
A44: EBITDA | B44: =B8-B42 | C44: =C8-C42 | D44: =D8-D42 | E44: =E8-E42 | F44: =F8-F42 | G44: =G8-G42 | H44: =H8-H42 | I44: =I8-I42 | ... M44: =M8-M42

Sheet Sensitivity Analysis
A1: REVISED SENSITIVITY ANALYSIS - PAYBACK PERIOD (Years)
A2: Conservative: Spa €30K/mo, No Aesthetics | Base: Spa €30K + Aes Ramp | Optimistic: Spa €45K + Aes €45-50K
A4: Scenario | B4: €300K Capex | C4: €400K Capex | D4: €500K Capex
A5: CONSERVATIVE | B5: 4.14 | C5: 5.52 | D5: 6.9
A6: BASE CASE | B6: 2.43 | C6: 3.24 | D6: 4.05
A7: OPTIMISTIC | B7: 0.77 | C7: 1.03 | D7: 1.29
A10: DETAILED SCENARIO BREAKDOWN
A12: Metric | B12: Conservative | C12: Base Case | D12: Optimistic
A13: Spa Revenue (€/month) | B13: 30000 | C13: 30000 | D13: 45000
A14: Aesthetics Revenue (€/month avg) | B14: 0 | C14: 17750 | D14: 32500
A15: Total Annual Revenue | B15: 360000 | C15: 573000 | D15: 930000
A17: Annual Payroll | B17: 166800 | C17: 272450 | D17: 300300
A18: Annual OpEx + COGS | B18: 120720 | C18: 177165 | D18: 241740
A19: YEAR 1 EBITDA | B19: 72480 | C19: 123385 | D19: 387630
A20: EBITDA Margin | B20: 0.201 | C20: 0.215 | D20: 0.417
A23: KEY INSIGHTS
A24: Conservative (No Clinic): | B24: Payback in 4-7 years. Spa-only business, stable but limited upside.
A25: Base Case (Clinic Added): | B25: Payback in 2.4-4 years. €123K EBITDA with clinic operations.
A26: Optimistic (Full Potential): | B26: Payback in 0.8-1.3 years. €388K EBITDA with strong clinic growth.
A28: Best Case Scenario: | B28: €300K capex, optimistic growth = payback in 9.2 months
A29: Worst Case Scenario: | B29: €500K capex, conservative case = payback in 6.9 years
A30: Most Likely: | B30: €400K capex, base case = payback in 3.2 years
